Workbook

Sheet Executive Summary
A1: U.S. Airline Operations & Delay Root-Cause Analytics
A2: Executive summary | BTS Reporting Carrier On-Time Performance | Complete 2023–2025 monthly files | 20.93M scheduled domestic-flight records
A4: Scheduled Flights | D4: On-Time Rate | G4: Arrival Delay Rate | J4: Cancellation Rate
A5: =SUM('Delay Trends'!D5:D40) -> 20928579 | D5: =SUM('Delay Trends'!K5:K40)/SUM('Delay Trends'!E5:E40) -> 0.77520533 | G5: =SUM('Delay Trends'!L5:L40)/SUM('Delay Trends'!E5:E40) -> 0.20860733 | J5: =SUM('Delay Trends'!M5:M40)/SUM('Delay Trends'!D5:D40) -> 0.013719708
A9: Operational findings
A10: 2025 reliability | B10: On-time performance fell from 78.2% in 2023 to 76.3% in 2025 while the arrival-delay rate rose from 20.3% to 21.9%.
A11: Later-day risk | B11: Evening flights had a 28.7% observed delay rate and afternoon flights 27.5%, versus 13.4% in the morning across the full period.
A12: Delay propagation | B12: Late-aircraft delay was 39.2% of reported delay minutes in 2025, the largest reported category.
A13: High-volume diagnostics | B13: FLL, MIA, DFW, MCO, and CLT have elevated observed delay rates after the 5,000-departure threshold; comparisons require route/season context.
A15: Recommended operational focus (associational evidence, not causal claims)
A16: Recommendation | B16: Supporting finding | C16: Recommended action | D16: Limitation
A17: Protect later-day operations | B17: Later-day observed delay rates are roughly double morning levels. | C17: Prioritize recovery buffers, turn-time monitoring, and constrained-airport playbooks for afternoon/evening banks. | D17: Time of day is correlated with route mix, weather, and schedule design.
A18: Reduce delay propagation | B18: Late-aircraft delay was 39.2% of reported 2025 delay minutes. | C18: Review aircraft rotations, crew options, and connection-risk routes for recovery opportunities. | D18: Reported cause categories are operational classifications, not experiments.
A19: Use thresholded airport reviews | B19: DFW and CLT combine high volume with elevated observed delay rates. | C19: Segment reviews by departure period, season, carrier, and route before allocating resources. | D19: Airport comparisons reflect traffic, weather, and route-mix differences.
A20: Monitor cancellations separately | B20: ASE 6.61%; LGA 2.70%; EWR 2.61%; DCA 2.33% cancellation rates. | C20: Maintain separate cancellation/diversion controls alongside delay monitoring. | D20: Local weather, airport constraints, and airline schedules differ.

Sheet Delay Drivers
A1: Delay Drivers
A2: Reported delay-minute causes and departure-period patterns. Reported cause minutes apply to delayed operations and are not a causal experiment.
A4: Year | B4: Carrier Minutes | C4: Weather Minutes | D4: NAS Minutes | E4: Security Minutes | F4: Late Aircraft Minutes | G4: Total Reported Delay Minutes | I4: 2025 Cause | J4: Share of Reported Delay Minutes | L4: Year | M4: Month | N4: Departure Period | O4: Flights | P4: Delay Rate | Q4: On-Time Rate | R4: Mean Arrival Delay (min)
A5: 2023 | B5: 34862074 | C5: 5009341 | D5: 17310028 | E5: 206677 | F5: 38310004 | G5: 95698124 | I5: Late Aircraft | J5: =F7/G7 -> 0.3918624 | L5: 2023 | M5: 1 | N5: Afternoon | O5: 128301 | P5: 0.25536824 | Q5: 0.72325235 | R5: 10.853287
A6: 2024 | B6: 35823263 | C6: 6195873 | D6: 19621964 | E6: 179928 | F6: 41973684 | G6: 103794712 | I6: Carrier | J6: =B7/G7 -> 0.32453208 | L6: 2023 | M6: 1 | N6: Evening | O6: 88348 | P6: 0.26564269 | Q6: 0.71128945 | R6: 11.932244
A7: 2025 | B7: 36326377 | C7: 7108714 | D7: 24483761 | E7: 152802 | F7: 43862971 | G7: 111934625 | I7: NAS | J7: =D7/G7 -> 0.21873268 | L7: 2023 | M7: 1 | N7: Midday | O7: 131035 | P7: 0.22066623 | Q7: 0.75756859 | R7: 8.0177091
I8: Weather | J8: =C7/G7 -> 0.063507731 | L8: 2023 | M8: 1 | N8: Morning | O8: 175656 | P8: 0.16708225 | Q8: 0.81210434 | R8: 3.6984535
I9: Security | J9: =E7/G7 -> 0.0013651004 | L9: 2023 | M9: 1 | N9: Overnight | O9: 15497 | P9: 0.14299542 | Q9: 0.83435504 | R9: 2.854483
L10: 2023 | M10: 2 | N10: Afternoon | O10: 119501 | P10: 0.22462574 | Q10: 0.75621961 | R10: 7.7405982
L11: 2023 | M11: 2 | N11: Evening | O11: 84162 | P11: 0.23282479 | Q11: 0.74659585 | R11: 8.9286789
I12: Key pattern: observed delay risk increases later in the day. Across 2023–2025, evening was 28.7%, afternoon 27.5%, midday 20.6%, morning 13.4%, and overnight 9.7%. | L12: 2023 | M12: 2 | N12: Midday | O12: 121209 | P12: 0.18968063 | Q12: 0.79312592 | R12: 4.3466275
L13: 2023 | M13: 2 | N13: Morning | O13: 163662 | P13: 0.13463724 | Q13: 0.84377559 | R13: -0.53185869
L14: 2023 | M14: 2 | N14: Overnight | O14: 14215 | P14: 0.10587408 | Q14: 0.86851917 | R14: -2.5237167
L15: 2023 | M15: 3 | N15: Afternoon | O15: 136487 | P15: 0.29066505 | Q15: 0.69166294 | R15: 14.370748
L16: 2023 | M16: 3 | N16: Evening | O16: 101982 | P16: 0.30996646 | Q16: 0.66925536 | R16: 16.096422
L17: 2023 | M17: 3 | N17: Midday | O17: 136561 | P17: 0.23512569 | Q17: 0.75119544 | R17: 8.7173944
L18: 2023 | M18: 3 | N18: Morning | O18: 187427 | P18: 0.16373308 | Q18: 0.82467841 | R18: 2.664646
L19: 2023 | M19: 3 | N19: Overnight | O19: 17865 | P19: 0.10993563 | Q19: 0.87786174 | R19: -1.0344534
L20: 2023 | M20: 4 | N20: Afternoon | O20: 131684 | P20: 0.28284378 | Q20: 0.69285562 | R20: 14.743867
L21: 2023 | M21: 4 | N21: Evening | O21: 98392 | P21: 0.31151923 | Q21: 0.66306204 | R21: 17.168014
L22: 2023 | M22: 4 | N22: Midday | O22: 132226 | P22: 0.22464568 | Q22: 0.75798255 | R22: 8.9984453
L23: 2023 | M23: 4 | N23: Morning | O23: 181530 | P23: 0.1465598 | Q23: 0.83756955 | R23: 1.837038
L24: 2023 | M24: 4 | N24: Overnight | O24: 17609 | P24: 0.095178602 | Q24: 0.8870464 | R24: -1.3619334
... L186: 2025 | M186: 12 | N186: Overnight | O186: 18799 | P186: 0.12750678 | Q186: 0.85573701 | R186: 1.9239883

Sheet Airport Analysis
A1: Airport Analysis
A2: Airport-level observed performance. The source table includes origins with at least 5,000 scheduled departures; use volume and context before interpreting differences.
A4: Airport lookup (editable)
A5: Airport code | B5: EVV
A6: City | B6: =IFERROR(_xlfn.SINGLE(_xlfn.XLOOKUP($B$5, $A$15:$A$220, $B$15:$B$220)), "Not found") -> Evansville, IN
A7: Departures | B7: =IFERROR(_xlfn.SINGLE(_xlfn.XLOOKUP($B$5, $A$15:$A$220, $D$15:$D$220)), 0) -> 5943
A8: Delay rate | B8: =IFERROR(_xlfn.SINGLE(_xlfn.XLOOKUP($B$5, $A$15:$A$220, $E$15:$E$220)), 0) -> 0.19552415
A9: Cancellation rate | B9: =IFERROR(_xlfn.SINGLE(_xlfn.XLOOKUP($B$5, $A$15:$A$220, $F$15:$F$220)), 0) -> 0.014470806
A10: Mean arrival delay | B10: =IFERROR(_xlfn.SINGLE(_xlfn.XLOOKUP($B$5, $A$15:$A$220, $H$15:$H$220)), 0) -> 6.4262941
A14: Airport | B14: City | C14: State | D14: Departures | E14: Delay Rate | F14: Cancellation Rate | G14: Diversion Rate | H14: Mean Arrival Delay (min)
A15: ASE | B15: Aspen, CO | C15: CO | D15: 22164 | E15: 0.29272694 | F15: 0.066143295 | G15: 0.0064067858 | H15: 21.663651
A16: FLL | B16: Fort Lauderdale, FL | C16: FL | D16: 269310 | E16: 0.26827448 | F16: 0.015736512 | G16: 0.0029705544 | H16: 13.318032
A17: EGE | B17: Eagle, CO | C17: CO | D17: 10664 | E17: 0.26594149 | F17: 0.014066017 | G17: 0.0069392348 | H17: 16.4
A18: MIA | B18: Miami, FL | C18: FL | D18: 324386 | E18: 0.26580679 | F18: 0.01344386 | G18: 0.0030858298 | H18: 13.49122
A19: SFB | B19: Sanford, FL | C19: FL | D19: 29096 | E19: 0.26546604 | F19: 0.0083172945 | G19: 0.0027495188 | H19: 13.508966
A20: DFW | B20: Dallas/Fort Worth, TX | C20: TX | D20: 914680 | E20: 0.26033913 | F20: 0.020725281 | G20: 0.0028917217 | H20: 13.440982
A21: HDN | B21: Hayden, CO | C21: CO | D21: 7183 | E21: 0.25490742 | F21: 0.017123764 | G21: 0.0025059167 | H21: 12.560068 | J21: Interpretation guardrail: this is a thresholded operational-screening list, not an airport-quality ranking. Compare within season, departure period, carrier, and route before taking action.
A22: MCO | B22: Orlando, FL | C22: FL | D22: 483970 | E22: 0.25477199 | F22: 0.013878959 | G22: 0.0024774263 | H22: 12.49023
A23: BQN | B23: Aguadilla, PR | C23: PR | D23: 7641 | E23: 0.25022903 | F23: 0.01701348 | G23: 0.0039261877 | H23: 11.728245
A24: CLT | B24: Charlotte, NC | C24: NC | D24: 608080 | E24: 0.24520293 | F24: 0.013317327 | G24: 0.0023121958 | H24: 11.459165
A25: DEN | B25: Denver, CO | C25: CO | D25: 915316 | E25: 0.24369398 | F25: 0.010876025 | G25: 0.0027935707 | H25: 9.7447475
A26: SJU | B26: San Juan, PR | C26: PR | D26: 103721 | E26: 0.24225567 | F26: 0.010952459 | G26: 0.0045988758 | H26: 12.291946
A27: TVC | B27: Traverse City, MI | C27: MI | D27: 13233 | E27: 0.2420464 | F27: 0.016398398 | G27: 0.0024181969 | H27: 13.578866
A28: JAC | B28: Jackson, WY | C28: WY | D28: 17223 | E28: 0.23991175 | F28: 0.014050978 | G28: 0.0081867271 | H28: 15.502019
A29: FNT | B29: Flint, MI | C29: MI | D29: 7598 | E29: 0.23979995 | F29: 0.011318768 | G29: 0.0022374309 | H29: 11.91034
A30: BWI | B30: Baltimore, MD | C30: MD | D30: 290943 | E30: 0.23967925 | F30: 0.011827059 | G30: 0.0020931935 | H30: 8.4720157
A31: ORD | B31: Chicago, IL | C31: IL | D31: 865947 | E31: 0.23831944 | F31: 0.01454246 | G31: 0.00272534 | H31: 10.225715
A32: PBI | B32: West Palm Beach/Palm Beach, FL | C32: FL | D32: 87356 | E32: 0.2365264 | F32: 0.01600348 | G32: 0.0035143551 | H32: 12.394753
A33: FWA | B33: Fort Wayne, IN | C33: IN | D33: 15597 | E33: 0.23318587 | F33: 0.013912932 | G33: 0.0023081362 | H33: 12.676942
... A220: ITO | B220: Hilo, HI | C220: HI | D220: 20631 | E220: 0.12621783 | F220: 0.0084823809 | G220: 0.00019388299 | H220: 2.4740857

Sheet Carrier and Route Analysis
A1: Carrier and Route Analysis
A2: Carrier comparison uses route-month peer controls with a 100-flight carrier cell threshold; route performance uses a 1,000-flight threshold.
A4: Carrier | B4: Comparable Flights | C4: Comparable Delay Rate | D4: Route-Month Peer Rate | E4: Relative Delay Rate | G4: Route | H4: Origin | I4: Destination | J4: Flights | K4: Delay Rate | L4: Cancellation Rate | N4: Airport | O4: City | P4: State | Q4: Scheduled Flights | R4: Cancellation Rate | S4: Diversion Rate
A5: WN | B5: 2418827 | C5: 0.2114897 | D5: 0.20655904 | E5: 0.0049306609 | G5: DFW-SYR | H5: DFW | I5: SYR | J5: 1039 | K5: 0.4533205 | L5: 0.018286814 | N5: ASE | O5: Aspen, CO | P5: CO | Q5: 22164 | R5: 0.066143295 | S5: 0.0064067858
A6: DL | B6: 2101344 | C6: 0.17696151 | D6: 0.18329467 | E6: -0.0063331642 | G6: DFW-MDT | H6: DFW | I6: MDT | J6: 1096 | K6: 0.41788321 | L6: 0.012773723 | N6: BGR | O6: Bangor, ME | P6: ME | Q6: 13007 | R6: 0.035826862 | S6: 0.0026139771
A7: AA | B7: 1903689 | C7: 0.24664008 | D7: 0.24266217 | E7: 0.0039779097 | G7: DCA-AUS | H7: DCA | I7: AUS | J7: 1096 | K7: 0.40328467 | L7: 0.0072992701 | N7: TTN | O7: Trenton, NJ | P7: NJ | Q7: 5142 | R7: 0.032672112 | S7: 0.0036950603
A8: UA | B8: 1315510 | C8: 0.20820442 | D8: 0.22219748 | E8: -0.013993054 | G8: DEN-BUF | H8: DEN | I8: BUF | J8: 1322 | K8: 0.39863843 | L8: 0.0052950076 | N8: LGA | O8: New York, NY | P8: NY | Q8: 461883 | R8: 0.026967868 | S8: 0.0028080704
A9: OO | B9: 657153 | C9: 0.19654327 | D9: 0.20394742 | E9: -0.0074041539 | G9: BDL-SJU | H9: BDL | I9: SJU | J9: 2991 | K9: 0.3965229 | L9: 0.014042126 | N9: EWR | O9: Newark, NJ | P9: NJ | Q9: 387843 | R9: 0.026080141 | S9: 0.0024803851
A10: YX | B10: 386713 | C10: 0.16644643 | D10: 0.17841172 | E10: -0.011965281 | G10: SCK-LAS | H10: SCK | I10: LAS | J10: 1242 | K10: 0.38325282 | L10: 0.0064412238 | N10: CHO | O10: Charlottesville, VA | P10: VA | Q10: 7605 | R10: 0.025904011 | S10: 0.002103879
A11: B6 | B11: 327519 | C11: 0.26676315 | D11: 0.24700732 | E11: 0.019755832 | G11: DFW-GEG | H11: DFW | I11: GEG | J11: 1826 | K11: 0.38116101 | L11: 0.011500548 | N11: BTV | O11: Burlington, VT | P11: VT | Q11: 22485 | R11: 0.025661552 | S11: 0.0028018679
A12: AS | B12: 319140 | C12: 0.21526916 | D12: 0.19257066 | E12: 0.022698501 | G12: SNA-PVU | H12: SNA | I12: PVU | J12: 1081 | K12: 0.37835338 | L12: 0.018501388 | N12: GRK | O12: Killeen, TX | P12: TX | Q12: 5189 | R12: 0.025052997 | S12: 0.0011562922
A13: OH | B13: 209464 | C13: 0.21447122 | D13: 0.21449117 | E13: -1.9948661e-05 | G13: MIA-MEM | H13: MIA | I13: MEM | J13: 1278 | K13: 0.37793427 | L13: 0.011737089 | N13: COU | O13: Columbia, MO | P13: MO | Q13: 5687 | R13: 0.02426587 | S13: 0.0028134341
A14: MQ | B14: 196935 | C14: 0.19569909 | D14: 0.19762342 | E14: -0.001924328 | G14: DFW-BFL | H14: DFW | I14: BFL | J14: 1456 | K14: 0.37087912 | L14: 0.019230769 | N14: DCA | O14: Washington, DC | P14: VA | Q14: 422527 | R14: 0.023288453 | S14: 0.0023548791
A15: HA | B15: 157732 | C15: 0.1675944 | D15: 0.12970643 | E15: 0.037887975 | G15: DFW-BUF | H15: DFW | I15: BUF | J15: 1553 | K15: 0.3689633 | L15: 0.018673535 | N15: PWM | O15: Portland, ME | P15: ME | Q15: 33396 | R15: 0.023206372 | S15: 0.0025751587
A16: NK | B16: 96176 | C16: 0.27642031 | D16: 0.25509421 | E16: 0.021326103 | G16: SJU-BDL | H16: SJU | I16: BDL | J16: 2989 | K16: 0.36801606 | L16: 0.013382402 | N16: ILM | O16: Wilmington, NC | P16: NC | Q16: 22942 | R16: 0.022927382 | S16: 0.0020922326
... A18: F9 | B18: 43446 | C18: 0.27307462 | D18: 0.25088814 | E18: 0.02218648 | G18: PHL-SJU | H18: PHL | I18: SJU | J18: 4434 | K18: 0.35385656 | L18: 0.01623816 | N18: ROA | O18: Roanoke, VA | P18: VA | Q18: 7496 | R18: 0.021878335 | S18: 0.0014674493
G19: ASE-ATL | H19: ASE | I19: ATL | J19: 1125 | K19: 0.35377778 | L19: 0.062222222 | N19: LFT | O19: Lafayette, LA | P19: LA | Q19: 8855 | R19: 0.021682665 | S19: 0.0027103331
G20: FLL-TYS | H20: FLL | I20: TYS | J20: 1185 | K20: 0.3535865 | L20: 0.0067510549 | N20: BUF | O20: Buffalo, NY | P20: NY | Q20: 63669 | R20: 0.021517536 | S20: 0.0020732224
G21: DFW-MSN | H21: DFW | I21: MSN | J21: 3211 | K21: 0.35316101 | L21: 0.016817191 | N21: HHH | O21: Hilton Head, SC | P21: SC | Q21: 5861 | R21: 0.021327419 | S21: 0.0087015868
G22: JFK-BQN | H22: JFK | I22: BQN | J22: 1852 | K22: 0.35259179 | L22: 0.021058315 | N22: DFW | O22: Dallas/Fort Worth, TX | P22: TX | Q22: 914680 | R22: 0.020725281 | S22: 0.0028917217
G23: SRQ-DFW | H23: SRQ | I23: DFW | J23: 1179 | K23: 0.35114504 | L23: 0.031382528 | N23: JFK | O23: New York, NY | P23: NY | Q23: 361156 | R23: 0.020666969 | S23: 0.0025778334
G24: FLL-ALB | H24: FLL | I24: ALB | J24: 1288 | K24: 0.34860248 | L24: 0.011645963 | N24: ORF | O24: Norfolk, VA | P24: VA | Q24: 62201 | R24: 0.020610601 | S24: 0.002009614
G25: SJU-DCA | H25: SJU | I25: DCA | J25: 1096 | K25: 0.34854015 | L25: 0.0063868613 | N25: BTR | O25: Baton Rouge, LA | P25: LA | Q25: 13790 | R25: 0.020449601 | S25: 0.0023205221
G26: FLL-SAN | H26: FLL | I26: SAN | J26: 1138 | K26: 0.34797891 | L26: 0.0228471 | N26: CAE | O26: Columbia, SC | P26: SC | Q26: 18451 | R26: 0.020432497 | S26: 0.0023846946
G27: ASE-IAH | H27: ASE | I27: IAH | J27: 1752 | K27: 0.34303653 | L27: 0.070205479 | N27: AVL | O27: Asheville, NC | P27: NC | Q27: 33536 | R27: 0.020127624 | S27: 0.0033695134
G28: SAT-BOS | H28: SAT | I28: BOS | J28: 1037 | K28: 0.34233365 | L28: 0.013500482 | N28: KTN | O28: Ketchikan, AK | P28: AK | Q28: 7392 | R28: 0.019886364 | S28: 0.0029761905
G29: DEN-MLI | H29: DEN | I29: MLI | J29: 1099 | K29: 0.34212921 | L29: 0.011828935 | N29: MHT | O29: Manchester, NH | P29: NH | Q29: 17904 | R29: 0.019660411 | S29: 0.0031277927
G30: IAH-JFK | H30: IAH | I30: JFK | J30: 1039 | K30: 0.34167469 | L30: 0.024061598 | N30: MYR | O30: Myrtle Beach, SC | P30: SC | Q30: 44975 | R30: 0.019655364 | S30: 0.0021122846
... G210: ATL-MIA | H210: ATL | I210: MIA | J210: 19743 | K210: 0.28516436 | L210: 0.011041888 | N210: SGU | O210: St. George, UT | P210: UT | Q210: 10178 | R210: 0.0021615249 | S210: 0.0031440362
G211: ORD-CAK | H211: ORD | I211: CAK | J211: 3409 | K211: 0.2851276 | L211: 0.020533881
G212: DFW-FLL | H212: DFW | I212: FLL | J212: 8597 | K212: 0.28509945 | L212: 0.022798651 | N212: How to use this page: first identify a high-volume exception, then compare it with route-month peer performance, seasons, departure periods, and cancellation/diversion patterns. Do not infer that a carrier, airport, or route caused a delay from descriptive rankings.
G213: JFK-IAH | H213: JFK | I213: IAH | J213: 1039 | K213: 0.28488932 | L213: 0.014436959
G214: DEN-SDF | H214: DEN | I214: SDF | J214: 3289 | K214: 0.28488902 | L214: 0.0060808756
G215: MDW-PDX | H215: MDW | I215: PDX | J215: 1693 | K215: 0.28470171 | L215: 0.0047253396
G216: ORD-CHO | H216: ORD | I216: CHO | J216: 1760 | K216: 0.28465909 | L216: 0.018181818
G217: MCO-PHL | H217: MCO | I217: PHL | J217: 17168 | K217: 0.28448276 | L217: 0.016367661
G218: DFW-VPS | H218: DFW | I218: VPS | J218: 4099 | K218: 0.28445962 | L218: 0.023664308
G219: DEN-ATW | H219: DEN | I219: ATW | J219: 1322 | K219: 0.28441755 | L219: 0.015128593
G220: LAS-FLL | H220: LAS | I220: FLL | J220: 2835 | K220: 0.28430335 | L220: 0.0098765432
G221: SBP-DFW | H221: SBP | I221: DFW | J221: 1457 | K221: 0.2841455 | L221: 0.01509952
...

Sheet Data Quality
A1: Data Quality & Reconciliation
A2: Automated controls, source-to-model reconciliation, and analytical treatments. Each operational rate uses the denominator documented below.
A4: Reconciliation Check | B4: Source / Expected | C4: Workbook Result | D4: Status | F4: Quality Rule / Treatment | G4: Why | H4: Result
A5: Fact rows | B5: 20928579 | C5: ='Data Quality'!B5 -> 20928579 | D5: =IF(B5=C5,"PASS","FAIL") -> PASS | F5: Required keys | G5: Flight date, airline, origin, and destination are required for model joins. | H5: 20,928,579 retained fact rows; full source retention after required-key checks.
A6: Unique candidate flight keys | B6: 20928579 | C6: ='Data Quality'!B6 -> 20928579 | D6: =IF(B6=C6,"PASS","FAIL") -> PASS | F6: Candidate-key uniqueness | G6: Detect duplicate records before rate aggregation. | H6: 0 duplicate candidate-key rows.
A7: Duplicate candidate-key rows | B7: 0 | C7: ='Data Quality'!B7 -> 0 | D7: =IF(B7=C7,"PASS","FAIL") -> PASS | F7: Arrival fields | G7: Cancelled/diverted records have non-applicable arrival outcomes. | H7: 1.63% arrival-delay missingness, treated as expected; excluded only from arrival-performance denominators.
A8: Scheduled flights in presentation | B8: 20928579 | C8: =SUM('Delay Trends'!D5:D40) -> 20928579 | D8: =IF(B8=C8,"PASS","FAIL") -> PASS | F8: Cancellation code mapping | G8: Avoid masking missing cancellation reason labels. | H8: 0 cancelled flights with Unknown cancellation code.
A9: Cancelled flights | B9: 287134 | C9: =ROUND(SUM('Delay Trends'!M5:M40),0) -> 287134 | D9: =IF(B9=C9,"PASS","FAIL") -> PASS | F9: Airport threshold | G9: Reduce unstable low-volume airport rates. | H9: 5,000 scheduled departures required.
A10: Diverted flights | B10: 53309 | C10: =ROUND(SUM('Delay Trends'!N5:N40),0) -> 53309 | D10: =IF(B10=C10,"PASS","FAIL") -> PASS | F10: Route threshold | G10: Reduce unstable low-volume route rates. | H10: 1,000 scheduled flights required.
A11: Date coverage | B11: 2023-01-01 to 2025-12-31 | C11: ="2023-01-01 to 2025-12-31" -> 2023-01-01 to 2025-12-31 | D11: =IF(B11=C11,"PASS","FAIL") -> PASS | F11: Carrier route-month threshold | G11: Support comparable peer-control cells. | H11: 100 flights per carrier route-month cell required.
F12: Monthly partitions | G12: Confirm complete monthly coverage. | H12: =COUNTIFS('Delay Trends'!$D$5:$D$40,">0")&" populated months; expected 36." -> 36 populated months; expected 36.
A14: Grain: one scheduled domestic flight record. Arrival delay and on-time rates use operated, non-diverted flights; cancellation and diversion rates use all scheduled records. Two records have Unknown departure period and remain visible rather than silently reassigned.

Sheet Definitions
A1: Definitions, Methodology & Sources
A2: Portfolio handoff guide. Detailed SQL, Power Query, Python, model diagram, and documentation are stored with the project repository.
A4: Metric / Field | B4: Definition | D4: Model component | E4: Purpose
A5: Scheduled flights | B5: Count of BTS reporting-carrier flight records at the scheduled-flight grain. | D5: fact_flights | E5: One scheduled domestic flight record; operational flags, timing, and delay metrics.
A6: Operated flights | B6: Scheduled records excluding cancelled flights. | D6: dim_date | E6: Calendar attributes for 2023–2025 trend analysis.
A7: On-time rate | B7: Share of operated, non-diverted flights with arrival delay under 15 minutes. | D7: dim_airline | E7: Reporting airline key and code.
A8: Arrival delay rate | B8: Share of operated, non-diverted flights with arrival delay greater than 15 minutes. | D8: dim_airport | E8: Airport code, city, and state.
A9: Cancellation rate | B9: Cancelled scheduled flights divided by all scheduled flights. | D9: dim_route | E9: Origin-destination route key.
A10: Diversion rate | B10: Diverted scheduled flights divided by all scheduled flights.
A11: Departure period | B11: Scheduled departure-time categories: Overnight, Morning, Midday, Afternoon, Evening, or Unknown. | D11: Primary source
A12: Reported delay causes | B12: Carrier, weather, NAS, security, and late-aircraft minutes reported in BTS records; descriptive operational classifications. | D12: Bureau of Transportation Statistics (BTS), Reporting Carrier On-Time Performance. Official table information: https://www.transtats.bts.gov/TableInfo.asp?QO_fu146_anzr=b0-gvzr&gnoyr_VQ=FGJ
A13: Comparable carrier rate | B13: Carrier route-month performance only where the carrier cell has at least 100 flights, compared with peer carriers on the same route and month.
A14: Volume thresholds | B14: Airport: 5,000 scheduled departures; route: 1,000 scheduled flights; carrier route-month: 100 flights.
D15: Limitations: BTS data describes reported domestic flight operations and delay classifications. Descriptive differences are associations and may reflect route mix, airport conditions, weather, traffic management, airline schedules, and seasonality. The workbook does not claim a carrier, airport, or time period caused a delay. The raw source exceeds Excel worksheet limits; this workbook presents aggregated, reconciled tables while the full fact dataset remains in the reproducible DuckDB/Parquet model.

Sheet Delay Trends
A1: Delay Trends
A2: Monthly BTS domestic operations, complete 2023–2025 files. Rates use operated, non-diverted flights unless otherwise noted.
A4: Month | B4: Year | C4: Month # | D4: Scheduled Flights | E4: Operated Flights | F4: On-Time Rate | G4: Arrival Delay Rate | H4: Cancellation Rate | I4: Diversion Rate | J4: Avg Arrival Delay (min) | K4: On-Time Flights (calc) | L4: Delayed Flights (calc) | M4: Cancelled Flights (calc) | N4: Diverted Flights (calc) | P4: Year | Q4: Scheduled Flights | R4: Operated Flights | S4: On-Time Rate | T4: Arrival Delay Rate | U4: Cancellation Rate | V4: Diversion Rate
A5: Jan 2023 | B5: 2023 | C5: 1 | D5: 538837 | E5: 527197 | F5: 0.76179624 | G5: 0.21660168 | H5: 0.019105963 | I5: 0.0024961166 | J5: 7.7763929 | K5: =E5*F5 -> 401616.69 | L5: =E5*G5 -> 114191.76 | M5: =D5*H5 -> 10295 | N5: =D5*I5 -> 1345 | P5: 2023 | Q5: =SUMIFS($D$5:$D$40,$B$5:$B$40,$P5) -> 6847899 | R5: =SUMIFS($E$5:$E$40,$B$5:$B$40,$P5) -> 6743404 | S5: =SUMIFS($K$5:$K$40,$B$5:$B$40,$P5)/R5 -> 0.7826203 | T5: =SUMIFS($L$5:$L$40,$B$5:$B$40,$P5)/R5 -> 0.20218528 | U5: =SUMIFS($M$5:$M$40,$B$5:$B$40,$P5)/Q5 -> 0.012842333 | V5: =SUMIFS($N$5:$N$40,$B$5:$B$40,$P5)/Q5 -> 0.0024170917
A6: Feb 2023 | B6: 2023 | C6: 2 | D6: 502749 | E6: 492747 | F6: 0.79518408 | G6: 0.1849213 | H6: 0.017939369 | I6: 0.00195525 | J6: 4.1419877 | K6: =E6*F6 -> 391824.57 | L6: =E6*G6 -> 91119.417 | M6: =D6*H6 -> 9019 | N6: =D6*I6 -> 983 | P6: 2024 | Q6: =SUMIFS($D$5:$D$40,$B$5:$B$40,$P6) -> 7079061 | R6: =SUMIFS($E$5:$E$40,$B$5:$B$40,$P6) -> 6965247 | S6: =SUMIFS($K$5:$K$40,$B$5:$B$40,$P6)/R6 -> 0.77955182 | T6: =SUMIFS($L$5:$L$40,$B$5:$B$40,$P6)/R6 -> 0.20447766 | U6: =SUMIFS($M$5:$M$40,$B$5:$B$40,$P6)/Q6 -> 0.013605618 | V6: =SUMIFS($N$5:$N$40,$B$5:$B$40,$P6)/Q6 -> 0.002471938
A7: Mar 2023 | B7: 2023 | C7: 3 | D7: 580322 | E7: 571533 | F7: 0.75042649 | G7: 0.23442847 | H7: 0.01276188 | I7: 0.0023831597 | J7: 9.0699067 | K7: =E7*F7 -> 428893.5 | L7: =E7*G7 -> 133983.61 | M7: =D7*H7 -> 7406 | N7: =D7*I7 -> 1383 | P7: 2025 | Q7: =SUMIFS($D$5:$D$40,$B$5:$B$40,$P7) -> 7001619 | R7: =SUMIFS($E$5:$E$40,$B$5:$B$40,$P7) -> 6879485 | S7: =SUMIFS($K$5:$K$40,$B$5:$B$40,$P7)/R7 -> 0.76353636 | T7: =SUMIFS($L$5:$L$40,$B$5:$B$40,$P7)/R7 -> 0.21908351 | U7: =SUMIFS($M$5:$M$40,$B$5:$B$40,$P7)/Q7 -> 0.014693173 | V7: =SUMIFS($N$5:$N$40,$B$5:$B$40,$P7)/Q7 -> 0.0027505067
A8: Apr 2023 | B8: 2023 | C8: 4 | D8: 561441 | E8: 550249 | F8: 0.75585324 | G8: 0.22421234 | H8: 0.017079266 | I8: 0.0028551531 | J8: 9.1129598 | K8: =E8*F8 -> 415907.49 | L8: =E8*G8 -> 123372.62 | M8: =D8*H8 -> 9589 | N8: =D8*I8 -> 1603
A9: May 2023 | B9: 2023 | C9: 5 | D9: 579958 | E9: 575430 | F9: 0.81266402 | G9: 0.17952852 | H9: 0.0057073098 | I9: 0.0021001521 | J9: 3.8132541 | K9: =E9*F9 -> 467631.26 | L9: =E9*G9 -> 103306.09 | M9: =D9*H9 -> 3310 | N9: =D9*I9 -> 1218 | P9: Interpretation: 2025 on-time performance was lower and delay/cancellation rates were higher than in 2023. Use airport, route, season, and departure-period cuts before attributing performance differences to any single operator.
A10: Jun 2023 | B10: 2023 | C10: 6 | D10: 577262 | E10: 562804 | F10: 0.71117794 | G10: 0.26377624 | H10: 0.021167165 | I10: 0.0038786548 | J10: 14.405798 | K10: =E10*F10 -> 400253.79 | L10: =E10*G10 -> 148454.32 | M10: =D10*H10 -> 12219 | N10: =D10*I10 -> 2239
A11: Jul 2023 | B11: 2023 | C11: 7 | D11: 601866 | E11: 585058 | F11: 0.6944702 | G11: 0.27760332 | H11: 0.02426786 | I11: 0.0036586217 | J11: 16.641825 | K11: =E11*F11 -> 406305.34 | L11: =E11*G11 -> 162414.04 | M11: =D11*H11 -> 14606 | N11: =D11*I11 -> 2202
A12: Aug 2023 | B12: 2023 | C12: 8 | D12: 602987 | E12: 592142 | F12: 0.76900995 | G12: 0.21300459 | H12: 0.015210942 | I12: 0.0027745208 | J12: 8.440266 | K12: =E12*F12 -> 455363.09 | L12: =E12*G12 -> 126128.97 | M12: =D12*H12 -> 9172 | N12: =D12*I12 -> 1673 | P12: Row Labels | Q12: Sum of Scheduled Flights
A13: Sep 2023 | B13: 2023 | C13: 9 | D13: 569338 | E13: 560887 | F13: 0.80126041 | G13: 0.18389603 | H13: 0.012396854 | I13: 0.0024467013 | J13: 5.3939742 | K13: =E13*F13 -> 449416.55 | L13: =E13*G13 -> 103144.89 | M13: =D13*H13 -> 7058 | N13: =D13*I13 -> 1393 | P13: 2023 | Q13: 6847899
A14: Oct 2023 | B14: 2023 | C14: 10 | D14: 598968 | E14: 596003 | F14: 0.8398078 | G14: 0.15524202 | H14: 0.0035728119 | I14: 0.0013773691 | J14: 1.1862558 | K14: =E14*F14 -> 500527.97 | L14: =E14*G14 -> 92524.707 | M14: =D14*H14 -> 2140 | N14: =D14*I14 -> 825 | P14: 2024 | Q14: 7079061
A15: Nov 2023 | B15: 2023 | C15: 11 | D15: 563777 | E15: 562413 | F15: 0.86215826 | G15: 0.13542234 | H15: 0.001452702 | I15: 0.00096669428 | J15: -1.2563383 | K15: =E15*F15 -> 484889.02 | L15: =E15*G15 -> 76163.284 | M15: =D15*H15 -> 819 | N15: =D15*I15 -> 545 | P15: 2025 | Q15: 7001619
A16: Dec 2023 | B16: 2023 | C16: 12 | D16: 570394 | E16: 566941 | F16: 0.83764556 | G16: 0.15630073 | H16: 0.0040498322 | I16: 0.002003878 | J16: 0.50933166 | K16: =E16*F16 -> 474895.61 | L16: =E16*G16 -> 88613.294 | M16: =D16*H16 -> 2310 | N16: =D16*I16 -> 1143 | P16: Grand Total | Q16: 20928579
A17: Jan 2024 | B17: 2024 | C17: 1 | D17: 547271 | E17: 525370 | F17: 0.72899898 | G17: 0.23098246 | H17: 0.037255765 | I17: 0.0027627994 | J17: 10.352298 | K17: =E17*F17 -> 382994.19 | L17: =E17*G17 -> 121351.25 | M17: =D17*H17 -> 20389 | N17: =D17*I17 -> 1512
A18: Feb 2024 | B18: 2024 | C18: 2 | D18: 519221 | E18: 515269 | F18: 0.83439037 | G18: 0.15799823 | H18: 0.0057817384 | I18: 0.0018296641 | J18: 0.59345507 | K18: =E18*F18 -> 429935.49 | L18: =E18*G18 -> 81411.591 | M18: =D18*H18 -> 3002 | N18: =D18*I18 -> 950
A19: Mar 2024 | B19: 2024 | C19: 3 | D19: 591767 | E19: 585413 | F19: 0.78304637 | G19: 0.2062163 | H19: 0.0086520539 | I19: 0.0020852802 | J19: 6.5044763 | K19: =E19*F19 -> 458405.52 | L19: =E19*G19 -> 120721.7 | M19: =D19*H19 -> 5120 | N19: =D19*I19 -> 1234
A20: Apr 2024 | B20: 2024 | C20: 4 | D20: 582185 | E20: 576915 | F20: 0.80209384 | G20: 0.18885406 | H20: 0.0069307866 | I20: 0.0021213188 | J20: 5.3605436 | K20: =E20*F20 -> 462739.97 | L20: =E20*G20 -> 108952.74 | M20: =D20*H20 -> 4035 | N20: =D20*I20 -> 1235
A21: May 2024 | B21: 2024 | C21: 5 | D21: 609743 | E21: 599226 | F21: 0.72317353 | G21: 0.25957822 | H21: 0.01352045 | I21: 0.0037278001 | J21: 14.04941 | K21: =E21*F21 -> 433344.38 | L21: =E21*G21 -> 155546.02 | M21: =D21*H21 -> 8244 | N21: =D21*I21 -> 2273
A22: Jun 2024 | B22: 2024 | C22: 6 | D22: 611132 | E22: 601272 | F22: 0.73850985 | G22: 0.24535616 | H22: 0.012887559 | I22: 0.0032464345 | J22: 11.807215 | K22: =E22*F22 -> 444045.29 | L22: =E22*G22 -> 147525.79 | M22: =D22*H22 -> 7876 | N22: =D22*I22 -> 1984
A23: Jul 2024 | B23: 2024 | C23: 7 | D23: 634613 | E23: 613938 | F23: 0.68084486 | G23: 0.28657623 | H23: 0.028949927 | I23: 0.0036289833 | J23: 18.092325 | K23: =E23*F23 -> 417996.53 | L23: =E23*G23 -> 175940.04 | M23: =D23*H23 -> 18372 | N23: =D23*I23 -> 2303
A24: Aug 2024 | B24: 2024 | C24: 8 | D24: 619025 | E24: 604303 | F24: 0.74712815 | G24: 0.22908929 | H24: 0.02053875 | I24: 0.0032438108 | J24: 10.587576 | K24: =E24*F24 -> 451491.78 | L24: =E24*G24 -> 138439.35 | M24: =D24*H24 -> 12714 | N24: =D24*I24 -> 2008
A25: Sep 2024 | B25: 2024 | C25: 9 | D25: 582622 | E25: 578262 | F25: 0.83859518 | G25: 0.15392141 | H25: 0.0060056091 | I25: 0.0014778021 | J25: 0.99677482 | K25: =E25*F25 -> 484927.73 | L25: =E25*G25 -> 89006.903 | M25: =D25*H25 -> 3499 | N25: =D25*I25 -> 861
A26: Oct 2024 | B26: 2024 | C26: 10 | D26: 615497 | E26: 608514 | F26: 0.85812116 | G26: 0.13053354 | H26: 0.010209635 | I26: 0.0011356676 | J26: -1.2827363 | K26: =E26*F26 -> 522178.74 | L26: =E26*G26 -> 79431.484 | M26: =D26*H26 -> 6284 | N26: =D26*I26 -> 699
A27: Nov 2024 | B27: 2024 | C27: 11 | D27: 575404 | E27: 571933 | F27: 0.84815712 | G27: 0.1458106 | H27: 0.0045689637 | I27: 0.0014633197 | J27: -0.32461145 | K27: =E27*F27 -> 485089.05 | L27: =E27*G27 -> 83393.891 | M27: =D27*H27 -> 2629 | N27: =D27*I27 -> 842
A28: Dec 2024 | B28: 2024 | C28: 12 | D28: 590581 | E28: 584832 | F28: 0.7807752 | G28: 0.20949032 | H28: 0.0070286718 | I28: 0.00270581 | J28: 7.1164403 | K28: =E28*F28 -> 456622.32 | L28: =E28*G28 -> 122516.64 | M28: =D28*H28 -> 4151 | N28: =D28*I28 -> 1598
... A40: Dec 2025 | B40: 2025 | C40: 12 | D40: 582304 | E40: 571924 | F40: 0.71923085 | G40: 0.26294341 | H40: 0.015457562 | I40: 0.0023681788 | J40: 13.041888 | K40: =E40*F40 -> 411345.38 | L40: =E40*G40 -> 150383.65 | M40: =D40*H40 -> 9001 | N40: =D40*I40 -> 1379
